470013 !! Traceback (most recent call last):  File "main.py", line 20, in <module>    with open('APIC'+str(cur[4])+'\\' + cur[1], 'wb') as outfile:OSError: [Errno 22] Invalid argument: 'APIC2\\anime-pictures.net - 470013 - misc ~ ryisu_(deluxe<<<) (deluxe<<<).jpg'

470012 !! Traceback (most recent call last):  File "main.py", line 20, in <module>    with open('APIC'+str(cur[4])+'\\' + cur[1], 'wb') as outfile:OSError: [Errno 22] Invalid argument: 'APIC2\\anime-pictures.net - 470012 - misc ~ ryisu_(deluxe<<<) (deluxe<<<).jpg'

470009 !! Traceback (most recent call last):  File "main.py", line 20, in <module>    with open('APIC'+str(cur[4])+'\\' + cur[1], 'wb') as outfile:OSError: [Errno 22] Invalid argument: 'APIC2\\anime-pictures.net - 470009 - misc ~ unknown (deluxe<<<).jpg'

470007 !! Traceback (most recent call last):  File "main.py", line 20, in <module>    with open('APIC'+str(cur[4])+'\\' + cur[1], 'wb') as outfile:OSError: [Errno 22] Invalid argument: 'APIC0\\anime-pictures.net - 470007 - misc ~ ryisu_(deluxe<<<) (deluxe<<<).jpg'

470006 !! Traceback (most recent call last):  File "main.py", line 20, in <module>    with open('APIC'+str(cur[4])+'\\' + cur[1], 'wb') as outfile:OSError: [Errno 22] Invalid argument: 'APIC2\\anime-pictures.net - 470006 - misc ~ unknown (deluxe<<<).jpg'

459321 !! Traceback (most recent call last):  File "main.py", line 20, in <module>    with open('APIC'+str(cur[4])+'\\' + cur[1], 'wb') as outfile:OSError: [Errno 22] Invalid argument: 'APIC0\\anime-pictures.net - 459321 - misc ~ unknown (deluxe<<<).jpg'

456962 !! Traceback (most recent call last):  File "main.py", line 20, in <module>    with open('APIC'+str(cur[4])+'\\' + cur[1], 'wb') as outfile:OSError: [Errno 22] Invalid argument: 'APIC2\\anime-pictures.net - 456962 - misc ~ ryisu_(deluxe<<<) (deluxe<<<).jpg'

^C

101034 !! Traceback (most recent call last):  File "C:\Programs\Python37\lib\site-packages\urllib3\connection.py", line 141, in _new_conn    (self.host, self.port), self.timeout, **extra_kw)  File "C:\Programs\Python37\lib\site-packages\urllib3\util\connection.py", line 83, in create_connection    raise err  File "C:\Programs\Python37\lib\site-packages\urllib3\util\connection.py", line 73, in create_connection    sock.connect(sa)TimeoutError: [WinError 10060] Попытка установить соединение была безуспешной, т.к. от другого компьютера за требуемое время не получен нужный отклик, или было разорвано уже установленное соединение из-за неверного отклика уже подключенного компьютераDuring handling of the above exception, another exception occurred:Traceback (most recent call last):  File "C:\Programs\Python37\lib\site-packages\urllib3\connectionpool.py", line 601, in urlopen    chunked=chunked)  File "C:\Programs\Python37\lib\site-packages\urllib3\connectionpool.py", line 346, in _make_request    self._validate_conn(conn)  File "C:\Programs\Python37\lib\site-packages\urllib3\connectionpool.py", line 850, in _validate_conn    conn.connect()  File "C:\Programs\Python37\lib\site-packages\urllib3\connection.py", line 284, in connect    conn = self._new_conn()  File "C:\Programs\Python37\lib\site-packages\urllib3\connection.py", line 150, in _new_conn    self, "Failed to establish a new connection: %s" % e)urllib3.exceptions.NewConnectionError: <urllib3.connection.VerifiedHTTPSConnection object at 0x000001B83E9EB6C8>: Failed to establish a new connection: [WinError 10060] Попытка установить соединение была безуспешной, т.к. от другого компьютера за требуемое время не получен нужный отклик, или было разорвано уже установленное соединение из-за неверного отклика уже подключенного компьютераDuring handling of the above exception, another exception occurred:Traceback (most recent call last):  File "C:\Programs\Python37\lib\site-packages\requests\adapters.py", line 449, in send    timeout=timeout  File "C:\Programs\Python37\lib\site-packages\urllib3\connectionpool.py", line 639, in urlopen    _stacktrace=sys.exc_info()[2])  File "C:\Programs\Python37\lib\site-packages\urllib3\util\retry.py", line 388, in increment    raise MaxRetryError(_pool, url, error or ResponseError(cause))urllib3.exceptions.MaxRetryError: HTTPSConnectionPool(host='images.anime-pictures.net', port=443): Max retries exceeded with url: /16f/16ffbaf9285b8e24e5e93461c93e6cca.jpg (Caused by NewConnectionError('<urllib3.connection.VerifiedHTTPSConnection object at 0x000001B83E9EB6C8>: Failed to establish a new connection: [WinError 10060] Попытка установить соединение была безуспешной, т.к. от другого компьютера за требуемое время не получен нужный отклик, или было разорвано уже установленное соединение из-за неверного отклика уже подключенного компьютера'))During handling of the above exception, another exception occurred:Traceback (most recent call last):  File "main.py", line 19, in <module>    p = requests.get(l_url, headers=headerrs)  File "C:\Programs\Python37\lib\site-packages\requests\api.py", line 76, in get    return request('get', url, params=params, **kwargs)  File "C:\Programs\Python37\lib\site-packages\requests\api.py", line 61, in request    return session.request(method=method, url=url, **kwargs)  File "C:\Programs\Python37\lib\site-packages\requests\sessions.py", line 530, in request    resp = self.send(prep, **send_kwargs)  File "C:\Programs\Python37\lib\site-packages\requests\sessions.py", line 643, in send    r = adapter.send(request, **kwargs)  File "C:\Programs\Python37\lib\site-packages\requests\adapters.py", line 516, in send    raise ConnectionError(e, request=request)requests.exceptions.ConnectionError: HTTPSConnectionPool(host='images.anime-pictures.net', port=443): Max retries exceeded with url: /16f/16ffbaf9285b8e24e5e93461c93e6cca.jpg (Caused by NewConnectionError('<urllib3.connection.VerifiedHTTPSConnection object at 0x000001B83E9EB6C8>: Failed to establish a new connection: [WinError 10060] Попытка установить соединение была безуспешной, т.к. от другого компьютера за требуемое время не получен нужный отклик, или было разорвано уже установленное соединение из-за неверного отклика уже подключенного компьютера'))

^C